2025-02-14 10:41:21,308 - INFO - WorkBot - Welcome to Work protocol started.
2025-02-14 10:41:43,748 - INFO - WorkBot - Sorting downloaded orders.
2025-02-14 10:41:43,750 - INFO - WorkBot - Generating emails for GMs.
2025-02-14 10:42:33,995 - INFO - WorkBot - Welcome to Work protocol started.
2025-02-14 10:42:55,529 - INFO - WorkBot - Sorting downloaded orders.
2025-02-14 10:42:55,531 - INFO - WorkBot - Generating emails for GMs.
2025-02-14 10:43:37,371 - INFO - WorkBot - Welcome to Work protocol started.
2025-02-14 12:26:48,991 - ERROR - backend.craftable_bot.CraftableBot - Error in input_transfer: module 'time' has no attribute 'wait'
Traceback (most recent call last):
  File "/home/anigold/projects/IthacaBakery/RandomStuff/WorkBot/main/backend/logger/Logger.py", line 83, in wrapper
    return func(*args, **kwargs)
  File "/home/anigold/projects/IthacaBakery/RandomStuff/WorkBot/main/backend/craftable_bot/CraftableBot.py", line 320, in input_transfer
    self._enter_transfer_details(transfer)
    ~~~~~~~~~~~~~~~~~~~~~~~~~~~~^^^^^^^^^^
  File "/home/anigold/projects/IthacaBakery/RandomStuff/WorkBot/main/backend/craftable_bot/CraftableBot.py", line 363, in _enter_transfer_details
    self._change_calendar_date(transfer.date)
    ~~~~~~~~~~~~~~~~~~~~~~~~~~^^^^^^^^^^^^^^^
  File "/home/anigold/projects/IthacaBakery/RandomStuff/WorkBot/main/backend/craftable_bot/CraftableBot.py", line 677, in _change_calendar_date
    time.wait(2)
    ^^^^^^^^^
AttributeError: module 'time' has no attribute 'wait'
2025-02-14 12:28:15,282 - ERROR - backend.craftable_bot.CraftableBot - Error in input_transfer: 'set' object has no attribute 'items'
Traceback (most recent call last):
  File "/home/anigold/projects/IthacaBakery/RandomStuff/WorkBot/main/backend/logger/Logger.py", line 83, in wrapper
    return func(*args, **kwargs)
  File "/home/anigold/projects/IthacaBakery/RandomStuff/WorkBot/main/backend/craftable_bot/CraftableBot.py", line 322, in input_transfer
    self._input_transfer_items(transfer.items)
    ~~~~~~~~~~~~~~~~~~~~~~~~~~^^^^^^^^^^^^^^^^
  File "/home/anigold/projects/IthacaBakery/RandomStuff/WorkBot/main/backend/craftable_bot/CraftableBot.py", line 412, in _input_transfer_items
    self.logger.info(f'Starting input for {len(transfer.items)} transfer items.')
                                               ^^^^^^^^^^^^^^
AttributeError: 'set' object has no attribute 'items'
2025-02-15 13:37:42,844 - ERROR - backend.craftable_bot.CraftableBot - Error in get_url: type object 'CraftableBot' has no attribute 'site_map'
Traceback (most recent call last):
  File "C:\Users\Will\Desktop\Andrew\Projects\RandomStuff\WorkBot\main\backend\logger\Logger.py", line 83, in wrapper
    return func(*args, **kwargs)
  File "C:\Users\Will\Desktop\Andrew\Projects\RandomStuff\WorkBot\main\backend\craftable_bot\CraftableBot.py", line 335, in get_url
    if key not in cls.site_map:
                  ^^^^^^^^^^^^
AttributeError: type object 'CraftableBot' has no attribute 'site_map'
2025-02-15 13:37:42,847 - ERROR - backend.craftable_bot.CraftableBot - Error in download_orders: type object 'CraftableBot' has no attribute 'site_map'
Traceback (most recent call last):
  File "C:\Users\Will\Desktop\Andrew\Projects\RandomStuff\WorkBot\main\backend\logger\Logger.py", line 83, in wrapper
    return func(*args, **kwargs)
  File "C:\Users\Will\Desktop\Andrew\Projects\RandomStuff\WorkBot\main\backend\craftable_bot\CraftableBot.py", line 181, in download_orders
    store_order_url = self.get_url('orders_page', store=store)
  File "C:\Users\Will\Desktop\Andrew\Projects\RandomStuff\WorkBot\main\backend\logger\Logger.py", line 83, in wrapper
    return func(*args, **kwargs)
  File "C:\Users\Will\Desktop\Andrew\Projects\RandomStuff\WorkBot\main\backend\craftable_bot\CraftableBot.py", line 335, in get_url
    if key not in cls.site_map:
                  ^^^^^^^^^^^^
AttributeError: type object 'CraftableBot' has no attribute 'site_map'
2025-02-15 13:38:59,003 - ERROR - backend.craftable_bot.CraftableBot - Error in get_url: type object 'CraftableBot' has no attribute 'stores'
Traceback (most recent call last):
  File "C:\Users\Will\Desktop\Andrew\Projects\RandomStuff\WorkBot\main\backend\logger\Logger.py", line 83, in wrapper
    return func(*args, **kwargs)
  File "C:\Users\Will\Desktop\Andrew\Projects\RandomStuff\WorkBot\main\backend\craftable_bot\CraftableBot.py", line 342, in get_url
    if store not in cls.stores:
                    ^^^^^^^^^^
AttributeError: type object 'CraftableBot' has no attribute 'stores'
2025-02-15 13:38:59,006 - ERROR - backend.craftable_bot.CraftableBot - Error in download_orders: type object 'CraftableBot' has no attribute 'stores'
Traceback (most recent call last):
  File "C:\Users\Will\Desktop\Andrew\Projects\RandomStuff\WorkBot\main\backend\logger\Logger.py", line 83, in wrapper
    return func(*args, **kwargs)
  File "C:\Users\Will\Desktop\Andrew\Projects\RandomStuff\WorkBot\main\backend\craftable_bot\CraftableBot.py", line 183, in download_orders
    store_order_url = self.get_url('orders_page', store=store)
  File "C:\Users\Will\Desktop\Andrew\Projects\RandomStuff\WorkBot\main\backend\logger\Logger.py", line 83, in wrapper
    return func(*args, **kwargs)
  File "C:\Users\Will\Desktop\Andrew\Projects\RandomStuff\WorkBot\main\backend\craftable_bot\CraftableBot.py", line 342, in get_url
    if store not in cls.stores:
                    ^^^^^^^^^^
AttributeError: type object 'CraftableBot' has no attribute 'stores'
2025-02-15 13:39:53,207 - ERROR - backend.craftable_bot.CraftableBot - Error in download_orders: Message: stale element reference: stale element not found in the current frame
  (Session info: chrome=133.0.6943.98); For documentation on this error, please visit: https://www.selenium.dev/documentation/webdriver/troubleshooting/errors#stale-element-reference-exception
Stacktrace:
	GetHandleVerifier [0x005702D3+25139]
	(No symbol) [0x004FB284]
	(No symbol) [0x003D04A3]
	(No symbol) [0x003D6EA1]
	(No symbol) [0x003D8F9A]
	(No symbol) [0x003D9017]
	(No symbol) [0x00417BC1]
	(No symbol) [0x0041868B]
	(No symbol) [0x0040DD71]
	(No symbol) [0x0043CF84]
	(No symbol) [0x0040D8E4]
	(No symbol) [0x0043D1B4]
	(No symbol) [0x0045E6E1]
	(No symbol) [0x0043CD36]
	(No symbol) [0x0040BD29]
	(No symbol) [0x0040D064]
	GetHandleVerifier [0x0087B193+3215603]
	GetHandleVerifier [0x0089230A+3310186]
	GetHandleVerifier [0x0088C522+3286146]
	GetHandleVerifier [0x00609CD0+654384]
	(No symbol) [0x0050460D]
	(No symbol) [0x005014F8]
	(No symbol) [0x00501697]
	(No symbol) [0x004F3D70]
	BaseThreadInitThunk [0x7673FCC9+25]
	RtlGetAppContainerNamedObjectPath [0x771682AE+286]
	RtlGetAppContainerNamedObjectPath [0x7716827E+238]
Traceback (most recent call last):
  File "C:\Users\Will\Desktop\Andrew\Projects\RandomStuff\WorkBot\main\backend\logger\Logger.py", line 83, in wrapper
    return func(*args, **kwargs)
  File "C:\Users\Will\Desktop\Andrew\Projects\RandomStuff\WorkBot\main\backend\craftable_bot\CraftableBot.py", line 193, in download_orders
    self._process_order_row(store, row, vendors, download_pdf, update)
    ~~~~~~~~~~~~~~~~~~~~~~~^^^^^^^^^^^^^^^^^^^^^^^^^^^^^^^^^^^^^^^^^^^
  File "C:\Users\Will\Desktop\Andrew\Projects\RandomStuff\WorkBot\main\backend\craftable_bot\CraftableBot.py", line 210, in _process_order_row
    row_data = row.find_elements(By.XPATH, './td')
  File "C:\Users\Will\Desktop\Andrew\Projects\RandomStuff\venv\Lib\site-packages\selenium\webdriver\remote\webelement.py", line 628, in find_elements
    return self._execute(Command.FIND_CHILD_ELEMENTS, {"using": by, "value": value})["value"]
           ~~~~~~~~~~~~~^^^^^^^^^^^^^^^^^^^^^^^^^^^^^^^^^^^^^^^^^^^^^^^^^^^^^^^^^^^^
  File "C:\Users\Will\Desktop\Andrew\Projects\RandomStuff\venv\Lib\site-packages\selenium\webdriver\remote\webelement.py", line 570, in _execute
    return self._parent.execute(command, params)
           ~~~~~~~~~~~~~~~~~~~~^^^^^^^^^^^^^^^^^
  File "C:\Users\Will\Desktop\Andrew\Projects\RandomStuff\venv\Lib\site-packages\selenium\webdriver\remote\webdriver.py", line 429, in execute
    self.error_handler.check_response(response)
    ~~~~~~~~~~~~~~~~~~~~~~~~~~~~~~~~~^^^^^^^^^^
  File "C:\Users\Will\Desktop\Andrew\Projects\RandomStuff\venv\Lib\site-packages\selenium\webdriver\remote\errorhandler.py", line 232, in check_response
    raise exception_class(message, screen, stacktrace)
selenium.common.exceptions.StaleElementReferenceException: Message: stale element reference: stale element not found in the current frame
  (Session info: chrome=133.0.6943.98); For documentation on this error, please visit: https://www.selenium.dev/documentation/webdriver/troubleshooting/errors#stale-element-reference-exception
Stacktrace:
	GetHandleVerifier [0x005702D3+25139]
	(No symbol) [0x004FB284]
	(No symbol) [0x003D04A3]
	(No symbol) [0x003D6EA1]
	(No symbol) [0x003D8F9A]
	(No symbol) [0x003D9017]
	(No symbol) [0x00417BC1]
	(No symbol) [0x0041868B]
	(No symbol) [0x0040DD71]
	(No symbol) [0x0043CF84]
	(No symbol) [0x0040D8E4]
	(No symbol) [0x0043D1B4]
	(No symbol) [0x0045E6E1]
	(No symbol) [0x0043CD36]
	(No symbol) [0x0040BD29]
	(No symbol) [0x0040D064]
	GetHandleVerifier [0x0087B193+3215603]
	GetHandleVerifier [0x0089230A+3310186]
	GetHandleVerifier [0x0088C522+3286146]
	GetHandleVerifier [0x00609CD0+654384]
	(No symbol) [0x0050460D]
	(No symbol) [0x005014F8]
	(No symbol) [0x00501697]
	(No symbol) [0x004F3D70]
	BaseThreadInitThunk [0x7673FCC9+25]
	RtlGetAppContainerNamedObjectPath [0x771682AE+286]
	RtlGetAppContainerNamedObjectPath [0x7716827E+238]

2025-02-15 13:40:45,810 - ERROR - backend.craftable_bot.CraftableBot - Error in download_orders: Message: stale element reference: stale element not found in the current frame
  (Session info: chrome=133.0.6943.98); For documentation on this error, please visit: https://www.selenium.dev/documentation/webdriver/troubleshooting/errors#stale-element-reference-exception
Stacktrace:
	GetHandleVerifier [0x005702D3+25139]
	(No symbol) [0x004FB284]
	(No symbol) [0x003D04A3]
	(No symbol) [0x003D6EA1]
	(No symbol) [0x003D8F9A]
	(No symbol) [0x003D9017]
	(No symbol) [0x00417BC1]
	(No symbol) [0x0041868B]
	(No symbol) [0x0040DD71]
	(No symbol) [0x0043CF84]
	(No symbol) [0x0040D8E4]
	(No symbol) [0x0043D1B4]
	(No symbol) [0x0045E6E1]
	(No symbol) [0x0043CD36]
	(No symbol) [0x0040BD29]
	(No symbol) [0x0040D064]
	GetHandleVerifier [0x0087B193+3215603]
	GetHandleVerifier [0x0089230A+3310186]
	GetHandleVerifier [0x0088C522+3286146]
	GetHandleVerifier [0x00609CD0+654384]
	(No symbol) [0x0050460D]
	(No symbol) [0x005014F8]
	(No symbol) [0x00501697]
	(No symbol) [0x004F3D70]
	BaseThreadInitThunk [0x7673FCC9+25]
	RtlGetAppContainerNamedObjectPath [0x771682AE+286]
	RtlGetAppContainerNamedObjectPath [0x7716827E+238]
Traceback (most recent call last):
  File "C:\Users\Will\Desktop\Andrew\Projects\RandomStuff\WorkBot\main\backend\logger\Logger.py", line 83, in wrapper
    return func(*args, **kwargs)
  File "C:\Users\Will\Desktop\Andrew\Projects\RandomStuff\WorkBot\main\backend\craftable_bot\CraftableBot.py", line 193, in download_orders
    self._process_order_row(store, row, vendors, download_pdf, update)
    ~~~~~~~~~~~~~~~~~~~~~~~^^^^^^^^^^^^^^^^^^^^^^^^^^^^^^^^^^^^^^^^^^^
  File "C:\Users\Will\Desktop\Andrew\Projects\RandomStuff\WorkBot\main\backend\craftable_bot\CraftableBot.py", line 210, in _process_order_row
    row_data = row.find_elements(By.XPATH, './td')
  File "C:\Users\Will\Desktop\Andrew\Projects\RandomStuff\venv\Lib\site-packages\selenium\webdriver\remote\webelement.py", line 628, in find_elements
    return self._execute(Command.FIND_CHILD_ELEMENTS, {"using": by, "value": value})["value"]
           ~~~~~~~~~~~~~^^^^^^^^^^^^^^^^^^^^^^^^^^^^^^^^^^^^^^^^^^^^^^^^^^^^^^^^^^^^
  File "C:\Users\Will\Desktop\Andrew\Projects\RandomStuff\venv\Lib\site-packages\selenium\webdriver\remote\webelement.py", line 570, in _execute
    return self._parent.execute(command, params)
           ~~~~~~~~~~~~~~~~~~~~^^^^^^^^^^^^^^^^^
  File "C:\Users\Will\Desktop\Andrew\Projects\RandomStuff\venv\Lib\site-packages\selenium\webdriver\remote\webdriver.py", line 429, in execute
    self.error_handler.check_response(response)
    ~~~~~~~~~~~~~~~~~~~~~~~~~~~~~~~~~^^^^^^^^^^
  File "C:\Users\Will\Desktop\Andrew\Projects\RandomStuff\venv\Lib\site-packages\selenium\webdriver\remote\errorhandler.py", line 232, in check_response
    raise exception_class(message, screen, stacktrace)
selenium.common.exceptions.StaleElementReferenceException: Message: stale element reference: stale element not found in the current frame
  (Session info: chrome=133.0.6943.98); For documentation on this error, please visit: https://www.selenium.dev/documentation/webdriver/troubleshooting/errors#stale-element-reference-exception
Stacktrace:
	GetHandleVerifier [0x005702D3+25139]
	(No symbol) [0x004FB284]
	(No symbol) [0x003D04A3]
	(No symbol) [0x003D6EA1]
	(No symbol) [0x003D8F9A]
	(No symbol) [0x003D9017]
	(No symbol) [0x00417BC1]
	(No symbol) [0x0041868B]
	(No symbol) [0x0040DD71]
	(No symbol) [0x0043CF84]
	(No symbol) [0x0040D8E4]
	(No symbol) [0x0043D1B4]
	(No symbol) [0x0045E6E1]
	(No symbol) [0x0043CD36]
	(No symbol) [0x0040BD29]
	(No symbol) [0x0040D064]
	GetHandleVerifier [0x0087B193+3215603]
	GetHandleVerifier [0x0089230A+3310186]
	GetHandleVerifier [0x0088C522+3286146]
	GetHandleVerifier [0x00609CD0+654384]
	(No symbol) [0x0050460D]
	(No symbol) [0x005014F8]
	(No symbol) [0x00501697]
	(No symbol) [0x004F3D70]
	BaseThreadInitThunk [0x7673FCC9+25]
	RtlGetAppContainerNamedObjectPath [0x771682AE+286]
	RtlGetAppContainerNamedObjectPath [0x7716827E+238]

2025-02-15 13:49:54,232 - ERROR - backend.craftable_bot.CraftableBot - Error in download_orders: [WinError 183] Cannot create a file when that file already exists: 'C:\\Users\\Will\\Desktop\\Andrew\\Projects\\RandomStuff\\WorkBot\\main\\backend\\downloads\\Order.pdf' -> 'C:\\Users\\Will\\Desktop\\Andrew\\Projects\\RandomStuff\\WorkBot\\main\\backend\\orders\\OrderFiles\\UNFI _ BAKERY 20250215.pdf'
Traceback (most recent call last):
  File "C:\Users\Will\Desktop\Andrew\Projects\RandomStuff\WorkBot\main\backend\logger\Logger.py", line 83, in wrapper
    return func(*args, **kwargs)
  File "C:\Users\Will\Desktop\Andrew\Projects\RandomStuff\WorkBot\main\backend\craftable_bot\CraftableBot.py", line 196, in download_orders
    self._process_order_row(store, row, vendors, download_pdf, update)
    ~~~~~~~~~~~~~~~~~~~~~~~^^^^^^^^^^^^^^^^^^^^^^^^^^^^^^^^^^^^^^^^^^^
  File "C:\Users\Will\Desktop\Andrew\Projects\RandomStuff\WorkBot\main\backend\craftable_bot\CraftableBot.py", line 251, in _process_order_row
    self._rename_new_order_file(store=store, vendor=row_vendor_name, date=row_date_formatted)
    ~~~~~~~~~~~~~~~~~~~~~~~~~~~^^^^^^^^^^^^^^^^^^^^^^^^^^^^^^^^^^^^^^^^^^^^^^^^^^^^^^^^^^^^^^
  File "C:\Users\Will\Desktop\Andrew\Projects\RandomStuff\WorkBot\main\backend\craftable_bot\CraftableBot.py", line 543, in _rename_new_order_file
    original_file.rename(new_filepath)
    ~~~~~~~~~~~~~~~~~~~~^^^^^^^^^^^^^^
  File "C:\Users\Will\AppData\Local\Programs\Python\Python313\Lib\pathlib\_local.py", line 767, in rename
    os.rename(self, target)
    ~~~~~~~~~^^^^^^^^^^^^^^
FileExistsError: [WinError 183] Cannot create a file when that file already exists: 'C:\\Users\\Will\\Desktop\\Andrew\\Projects\\RandomStuff\\WorkBot\\main\\backend\\downloads\\Order.pdf' -> 'C:\\Users\\Will\\Desktop\\Andrew\\Projects\\RandomStuff\\WorkBot\\main\\backend\\orders\\OrderFiles\\UNFI _ BAKERY 20250215.pdf'
2025-02-15 13:50:47,192 - ERROR - backend.craftable_bot.CraftableBot - Error in download_orders: Message: stale element reference: stale element not found in the current frame
  (Session info: chrome=133.0.6943.98); For documentation on this error, please visit: https://www.selenium.dev/documentation/webdriver/troubleshooting/errors#stale-element-reference-exception
Stacktrace:
	GetHandleVerifier [0x00AD02D3+25139]
	(No symbol) [0x00A5B284]
	(No symbol) [0x009304A3]
	(No symbol) [0x00936EA1]
	(No symbol) [0x00938F9A]
	(No symbol) [0x00939017]
	(No symbol) [0x00977BC1]
	(No symbol) [0x0097868B]
	(No symbol) [0x0096DD71]
	(No symbol) [0x0099CF84]
	(No symbol) [0x0096D8E4]
	(No symbol) [0x0099D1B4]
	(No symbol) [0x009BE6E1]
	(No symbol) [0x0099CD36]
	(No symbol) [0x0096BD29]
	(No symbol) [0x0096D064]
	GetHandleVerifier [0x00DDB193+3215603]
	GetHandleVerifier [0x00DF230A+3310186]
	GetHandleVerifier [0x00DEC522+3286146]
	GetHandleVerifier [0x00B69CD0+654384]
	(No symbol) [0x00A6460D]
	(No symbol) [0x00A614F8]
	(No symbol) [0x00A61697]
	(No symbol) [0x00A53D70]
	BaseThreadInitThunk [0x7673FCC9+25]
	RtlGetAppContainerNamedObjectPath [0x771682AE+286]
	RtlGetAppContainerNamedObjectPath [0x7716827E+238]
Traceback (most recent call last):
  File "C:\Users\Will\Desktop\Andrew\Projects\RandomStuff\WorkBot\main\backend\logger\Logger.py", line 83, in wrapper
    return func(*args, **kwargs)
  File "C:\Users\Will\Desktop\Andrew\Projects\RandomStuff\WorkBot\main\backend\craftable_bot\CraftableBot.py", line 196, in download_orders
    self._process_order_row(store, row, vendors, download_pdf, update)
    ~~~~~~~~~~~~~~~~~~~~~~~^^^^^^^^^^^^^^^^^^^^^^^^^^^^^^^^^^^^^^^^^^^
  File "C:\Users\Will\Desktop\Andrew\Projects\RandomStuff\WorkBot\main\backend\craftable_bot\CraftableBot.py", line 213, in _process_order_row
    row_data = row.find_elements(By.XPATH, './td')
  File "C:\Users\Will\Desktop\Andrew\Projects\RandomStuff\venv\Lib\site-packages\selenium\webdriver\remote\webelement.py", line 628, in find_elements
    return self._execute(Command.FIND_CHILD_ELEMENTS, {"using": by, "value": value})["value"]
           ~~~~~~~~~~~~~^^^^^^^^^^^^^^^^^^^^^^^^^^^^^^^^^^^^^^^^^^^^^^^^^^^^^^^^^^^^
  File "C:\Users\Will\Desktop\Andrew\Projects\RandomStuff\venv\Lib\site-packages\selenium\webdriver\remote\webelement.py", line 570, in _execute
    return self._parent.execute(command, params)
           ~~~~~~~~~~~~~~~~~~~~^^^^^^^^^^^^^^^^^
  File "C:\Users\Will\Desktop\Andrew\Projects\RandomStuff\venv\Lib\site-packages\selenium\webdriver\remote\webdriver.py", line 429, in execute
    self.error_handler.check_response(response)
    ~~~~~~~~~~~~~~~~~~~~~~~~~~~~~~~~~^^^^^^^^^^
  File "C:\Users\Will\Desktop\Andrew\Projects\RandomStuff\venv\Lib\site-packages\selenium\webdriver\remote\errorhandler.py", line 232, in check_response
    raise exception_class(message, screen, stacktrace)
selenium.common.exceptions.StaleElementReferenceException: Message: stale element reference: stale element not found in the current frame
  (Session info: chrome=133.0.6943.98); For documentation on this error, please visit: https://www.selenium.dev/documentation/webdriver/troubleshooting/errors#stale-element-reference-exception
Stacktrace:
	GetHandleVerifier [0x00AD02D3+25139]
	(No symbol) [0x00A5B284]
	(No symbol) [0x009304A3]
	(No symbol) [0x00936EA1]
	(No symbol) [0x00938F9A]
	(No symbol) [0x00939017]
	(No symbol) [0x00977BC1]
	(No symbol) [0x0097868B]
	(No symbol) [0x0096DD71]
	(No symbol) [0x0099CF84]
	(No symbol) [0x0096D8E4]
	(No symbol) [0x0099D1B4]
	(No symbol) [0x009BE6E1]
	(No symbol) [0x0099CD36]
	(No symbol) [0x0096BD29]
	(No symbol) [0x0096D064]
	GetHandleVerifier [0x00DDB193+3215603]
	GetHandleVerifier [0x00DF230A+3310186]
	GetHandleVerifier [0x00DEC522+3286146]
	GetHandleVerifier [0x00B69CD0+654384]
	(No symbol) [0x00A6460D]
	(No symbol) [0x00A614F8]
	(No symbol) [0x00A61697]
	(No symbol) [0x00A53D70]
	BaseThreadInitThunk [0x7673FCC9+25]
	RtlGetAppContainerNamedObjectPath [0x771682AE+286]
	RtlGetAppContainerNamedObjectPath [0x7716827E+238]

2025-02-15 13:58:12,204 - ERROR - backend.craftable_bot.CraftableBot - Error in download_orders: [WinError 183] Cannot create a file when that file already exists: 'C:\\Users\\Will\\Desktop\\Andrew\\Projects\\RandomStuff\\WorkBot\\main\\backend\\downloads\\Order.pdf' -> 'C:\\Users\\Will\\Desktop\\Andrew\\Projects\\RandomStuff\\WorkBot\\main\\backend\\orders\\OrderFiles\\UNFI _ BAKERY 20250215.pdf'
Traceback (most recent call last):
  File "C:\Users\Will\Desktop\Andrew\Projects\RandomStuff\WorkBot\main\backend\logger\Logger.py", line 83, in wrapper
    return func(*args, **kwargs)
  File "C:\Users\Will\Desktop\Andrew\Projects\RandomStuff\WorkBot\main\backend\craftable_bot\CraftableBot.py", line 198, in download_orders
    if self._process_order_row(store, row, vendors, download_pdf, update):
       ~~~~~~~~~~~~~~~~~~~~~~~^^^^^^^^^^^^^^^^^^^^^^^^^^^^^^^^^^^^^^^^^^^
  File "C:\Users\Will\Desktop\Andrew\Projects\RandomStuff\WorkBot\main\backend\craftable_bot\CraftableBot.py", line 260, in _process_order_row
    self._rename_new_order_file(store=store, vendor=row_vendor_name, date=row_date_formatted)
    ~~~~~~~~~~~~~~~~~~~~~~~~~~~^^^^^^^^^^^^^^^^^^^^^^^^^^^^^^^^^^^^^^^^^^^^^^^^^^^^^^^^^^^^^^
  File "C:\Users\Will\Desktop\Andrew\Projects\RandomStuff\WorkBot\main\backend\craftable_bot\CraftableBot.py", line 552, in _rename_new_order_file
    original_file.rename(new_filepath)
    ~~~~~~~~~~~~~~~~~~~~^^^^^^^^^^^^^^
  File "C:\Users\Will\AppData\Local\Programs\Python\Python313\Lib\pathlib\_local.py", line 767, in rename
    os.rename(self, target)
    ~~~~~~~~~^^^^^^^^^^^^^^
FileExistsError: [WinError 183] Cannot create a file when that file already exists: 'C:\\Users\\Will\\Desktop\\Andrew\\Projects\\RandomStuff\\WorkBot\\main\\backend\\downloads\\Order.pdf' -> 'C:\\Users\\Will\\Desktop\\Andrew\\Projects\\RandomStuff\\WorkBot\\main\\backend\\orders\\OrderFiles\\UNFI _ BAKERY 20250215.pdf'
2025-02-15 13:59:04,564 - ERROR - backend.craftable_bot.CraftableBot - Error in download_orders: [WinError 183] Cannot create a file when that file already exists: 'C:\\Users\\Will\\Desktop\\Andrew\\Projects\\RandomStuff\\WorkBot\\main\\backend\\downloads\\Order.pdf' -> 'C:\\Users\\Will\\Desktop\\Andrew\\Projects\\RandomStuff\\WorkBot\\main\\backend\\orders\\OrderFiles\\UNFI _ BAKERY 20250215.pdf'
Traceback (most recent call last):
  File "C:\Users\Will\Desktop\Andrew\Projects\RandomStuff\WorkBot\main\backend\logger\Logger.py", line 83, in wrapper
    return func(*args, **kwargs)
  File "C:\Users\Will\Desktop\Andrew\Projects\RandomStuff\WorkBot\main\backend\craftable_bot\CraftableBot.py", line 198, in download_orders
    if self._process_order_row(store, row, vendors, download_pdf, update):
       ~~~~~~~~~~~~~~~~~~~~~~~^^^^^^^^^^^^^^^^^^^^^^^^^^^^^^^^^^^^^^^^^^^
  File "C:\Users\Will\Desktop\Andrew\Projects\RandomStuff\WorkBot\main\backend\craftable_bot\CraftableBot.py", line 260, in _process_order_row
    self._rename_new_order_file(store=store, vendor=row_vendor_name, date=row_date_formatted)
    ~~~~~~~~~~~~~~~~~~~~~~~~~~~^^^^^^^^^^^^^^^^^^^^^^^^^^^^^^^^^^^^^^^^^^^^^^^^^^^^^^^^^^^^^^
  File "C:\Users\Will\Desktop\Andrew\Projects\RandomStuff\WorkBot\main\backend\craftable_bot\CraftableBot.py", line 552, in _rename_new_order_file
    original_file.rename(new_filepath)
    ~~~~~~~~~~~~~~~~~~~~^^^^^^^^^^^^^^
  File "C:\Users\Will\AppData\Local\Programs\Python\Python313\Lib\pathlib\_local.py", line 767, in rename
    os.rename(self, target)
    ~~~~~~~~~^^^^^^^^^^^^^^
FileExistsError: [WinError 183] Cannot create a file when that file already exists: 'C:\\Users\\Will\\Desktop\\Andrew\\Projects\\RandomStuff\\WorkBot\\main\\backend\\downloads\\Order.pdf' -> 'C:\\Users\\Will\\Desktop\\Andrew\\Projects\\RandomStuff\\WorkBot\\main\\backend\\orders\\OrderFiles\\UNFI _ BAKERY 20250215.pdf'
2025-02-15 14:00:08,160 - ERROR - backend.craftable_bot.CraftableBot - Error in download_orders: [WinError 183] Cannot create a file when that file already exists: 'C:\\Users\\Will\\Desktop\\Andrew\\Projects\\RandomStuff\\WorkBot\\main\\backend\\downloads\\Order.pdf' -> 'C:\\Users\\Will\\Desktop\\Andrew\\Projects\\RandomStuff\\WorkBot\\main\\backend\\orders\\OrderFiles\\UNFI _ BAKERY 20250215.pdf'
Traceback (most recent call last):
  File "C:\Users\Will\Desktop\Andrew\Projects\RandomStuff\WorkBot\main\backend\logger\Logger.py", line 83, in wrapper
    return func(*args, **kwargs)
  File "C:\Users\Will\Desktop\Andrew\Projects\RandomStuff\WorkBot\main\backend\craftable_bot\CraftableBot.py", line 198, in download_orders
    if self._process_order_row(store, row, vendors, download_pdf, update):
       ~~~~~~~~~~~~~~~~~~~~~~~^^^^^^^^^^^^^^^^^^^^^^^^^^^^^^^^^^^^^^^^^^^
  File "C:\Users\Will\Desktop\Andrew\Projects\RandomStuff\WorkBot\main\backend\craftable_bot\CraftableBot.py", line 260, in _process_order_row
    self._rename_new_order_file(store=store, vendor=row_vendor_name, date=row_date_formatted)
    ~~~~~~~~~~~~~~~~~~~~~~~~~~~^^^^^^^^^^^^^^^^^^^^^^^^^^^^^^^^^^^^^^^^^^^^^^^^^^^^^^^^^^^^^^
  File "C:\Users\Will\Desktop\Andrew\Projects\RandomStuff\WorkBot\main\backend\craftable_bot\CraftableBot.py", line 552, in _rename_new_order_file
    original_file.rename(new_filepath)
    ~~~~~~~~~~~~~~~~~~~~^^^^^^^^^^^^^^
  File "C:\Users\Will\AppData\Local\Programs\Python\Python313\Lib\pathlib\_local.py", line 767, in rename
    os.rename(self, target)
    ~~~~~~~~~^^^^^^^^^^^^^^
FileExistsError: [WinError 183] Cannot create a file when that file already exists: 'C:\\Users\\Will\\Desktop\\Andrew\\Projects\\RandomStuff\\WorkBot\\main\\backend\\downloads\\Order.pdf' -> 'C:\\Users\\Will\\Desktop\\Andrew\\Projects\\RandomStuff\\WorkBot\\main\\backend\\orders\\OrderFiles\\UNFI _ BAKERY 20250215.pdf'
2025-02-15 14:14:28,053 - ERROR - backend.craftable_bot.CraftableBot - Error in download_orders: [WinError 183] Cannot create a file when that file already exists: 'C:\\Users\\Will\\Desktop\\Andrew\\Projects\\RandomStuff\\WorkBot\\main\\backend\\downloads\\Order.pdf' -> 'C:\\Users\\Will\\Desktop\\Andrew\\Projects\\RandomStuff\\WorkBot\\main\\backend\\orders\\OrderFiles\\UNFI _ BAKERY 20250215.pdf'
Traceback (most recent call last):
  File "C:\Users\Will\Desktop\Andrew\Projects\RandomStuff\WorkBot\main\backend\logger\Logger.py", line 83, in wrapper
    return func(*args, **kwargs)
  File "C:\Users\Will\Desktop\Andrew\Projects\RandomStuff\WorkBot\main\backend\craftable_bot\CraftableBot.py", line 202, in download_orders
    if self._process_order_row(store, row, vendors, download_pdf, update):
       ~~~~~~~~~~~~~~~~~~~~~~~^^^^^^^^^^^^^^^^^^^^^^^^^^^^^^^^^^^^^^^^^^^
  File "C:\Users\Will\Desktop\Andrew\Projects\RandomStuff\WorkBot\main\backend\craftable_bot\CraftableBot.py", line 264, in _process_order_row
    self._rename_new_order_file(store=store, vendor=row_vendor_name, date=row_date_formatted)
    ~~~~~~~~~~~~~~~~~~~~~~~~~~~^^^^^^^^^^^^^^^^^^^^^^^^^^^^^^^^^^^^^^^^^^^^^^^^^^^^^^^^^^^^^^
  File "C:\Users\Will\Desktop\Andrew\Projects\RandomStuff\WorkBot\main\backend\craftable_bot\CraftableBot.py", line 556, in _rename_new_order_file
    original_file.rename(new_filepath)
    ~~~~~~~~~~~~~~~~~~~~^^^^^^^^^^^^^^
  File "C:\Users\Will\AppData\Local\Programs\Python\Python313\Lib\pathlib\_local.py", line 767, in rename
    os.rename(self, target)
    ~~~~~~~~~^^^^^^^^^^^^^^
FileExistsError: [WinError 183] Cannot create a file when that file already exists: 'C:\\Users\\Will\\Desktop\\Andrew\\Projects\\RandomStuff\\WorkBot\\main\\backend\\downloads\\Order.pdf' -> 'C:\\Users\\Will\\Desktop\\Andrew\\Projects\\RandomStuff\\WorkBot\\main\\backend\\orders\\OrderFiles\\UNFI _ BAKERY 20250215.pdf'
2025-02-15 14:15:32,190 - ERROR - backend.craftable_bot.CraftableBot - Error in download_orders: [WinError 183] Cannot create a file when that file already exists: 'C:\\Users\\Will\\Desktop\\Andrew\\Projects\\RandomStuff\\WorkBot\\main\\backend\\downloads\\Order.pdf' -> 'C:\\Users\\Will\\Desktop\\Andrew\\Projects\\RandomStuff\\WorkBot\\main\\backend\\orders\\OrderFiles\\UNFI _ BAKERY 20250215.pdf'
Traceback (most recent call last):
  File "C:\Users\Will\Desktop\Andrew\Projects\RandomStuff\WorkBot\main\backend\logger\Logger.py", line 83, in wrapper
    return func(*args, **kwargs)
  File "C:\Users\Will\Desktop\Andrew\Projects\RandomStuff\WorkBot\main\backend\craftable_bot\CraftableBot.py", line 202, in download_orders
    if self._process_order_row(store, row, vendors, download_pdf, update):
       ~~~~~~~~~~~~~~~~~~~~~~~^^^^^^^^^^^^^^^^^^^^^^^^^^^^^^^^^^^^^^^^^^^
  File "C:\Users\Will\Desktop\Andrew\Projects\RandomStuff\WorkBot\main\backend\craftable_bot\CraftableBot.py", line 264, in _process_order_row
    self._rename_new_order_file(store=store, vendor=row_vendor_name, date=row_date_formatted)
    ~~~~~~~~~~~~~~~~~~~~~~~~~~~^^^^^^^^^^^^^^^^^^^^^^^^^^^^^^^^^^^^^^^^^^^^^^^^^^^^^^^^^^^^^^
  File "C:\Users\Will\Desktop\Andrew\Projects\RandomStuff\WorkBot\main\backend\craftable_bot\CraftableBot.py", line 556, in _rename_new_order_file
    original_file.rename(new_filepath)
    ~~~~~~~~~~~~~~~~~~~~^^^^^^^^^^^^^^
  File "C:\Users\Will\AppData\Local\Programs\Python\Python313\Lib\pathlib\_local.py", line 767, in rename
    os.rename(self, target)
    ~~~~~~~~~^^^^^^^^^^^^^^
FileExistsError: [WinError 183] Cannot create a file when that file already exists: 'C:\\Users\\Will\\Desktop\\Andrew\\Projects\\RandomStuff\\WorkBot\\main\\backend\\downloads\\Order.pdf' -> 'C:\\Users\\Will\\Desktop\\Andrew\\Projects\\RandomStuff\\WorkBot\\main\\backend\\orders\\OrderFiles\\UNFI _ BAKERY 20250215.pdf'
2025-02-15 14:17:53,209 - ERROR - backend.craftable_bot.CraftableBot - Error in download_orders: [WinError 183] Cannot create a file when that file already exists: 'C:\\Users\\Will\\Desktop\\Andrew\\Projects\\RandomStuff\\WorkBot\\main\\backend\\downloads\\Order.pdf' -> 'C:\\Users\\Will\\Desktop\\Andrew\\Projects\\RandomStuff\\WorkBot\\main\\backend\\orders\\OrderFiles\\UNFI _ BAKERY 20250215.pdf'
Traceback (most recent call last):
  File "C:\Users\Will\Desktop\Andrew\Projects\RandomStuff\WorkBot\main\backend\logger\Logger.py", line 83, in wrapper
    return func(*args, **kwargs)
  File "C:\Users\Will\Desktop\Andrew\Projects\RandomStuff\WorkBot\main\backend\craftable_bot\CraftableBot.py", line 202, in download_orders
    if self._process_order_row(store, row, vendors, download_pdf, update):
       ~~~~~~~~~~~~~~~~~~~~~~~^^^^^^^^^^^^^^^^^^^^^^^^^^^^^^^^^^^^^^^^^^^
  File "C:\Users\Will\Desktop\Andrew\Projects\RandomStuff\WorkBot\main\backend\craftable_bot\CraftableBot.py", line 257, in _process_order_row
    self._rename_new_order_file(store=store, vendor=row_vendor_name, date=row_date_formatted)
    ~~~~~~~~~~~~~~~~~~~~~~~~~~~^^^^^^^^^^^^^^^^^^^^^^^^^^^^^^^^^^^^^^^^^^^^^^^^^^^^^^^^^^^^^^
  File "C:\Users\Will\Desktop\Andrew\Projects\RandomStuff\WorkBot\main\backend\craftable_bot\CraftableBot.py", line 549, in _rename_new_order_file
    original_file.rename(new_filepath)
    ~~~~~~~~~~~~~~~~~~~~^^^^^^^^^^^^^^
  File "C:\Users\Will\AppData\Local\Programs\Python\Python313\Lib\pathlib\_local.py", line 767, in rename
    os.rename(self, target)
    ~~~~~~~~~^^^^^^^^^^^^^^
FileExistsError: [WinError 183] Cannot create a file when that file already exists: 'C:\\Users\\Will\\Desktop\\Andrew\\Projects\\RandomStuff\\WorkBot\\main\\backend\\downloads\\Order.pdf' -> 'C:\\Users\\Will\\Desktop\\Andrew\\Projects\\RandomStuff\\WorkBot\\main\\backend\\orders\\OrderFiles\\UNFI _ BAKERY 20250215.pdf'
2025-02-15 14:19:52,168 - ERROR - backend.craftable_bot.CraftableBot - Error in download_orders: 'int' object is not iterable
Traceback (most recent call last):
  File "C:\Users\Will\Desktop\Andrew\Projects\RandomStuff\WorkBot\main\backend\logger\Logger.py", line 83, in wrapper
    return func(*args, **kwargs)
  File "C:\Users\Will\Desktop\Andrew\Projects\RandomStuff\WorkBot\main\backend\craftable_bot\CraftableBot.py", line 198, in download_orders
    for index in len(table_rows):
                 ~~~^^^^^^^^^^^^
TypeError: 'int' object is not iterable
2025-02-15 14:20:52,635 - ERROR - backend.craftable_bot.CraftableBot - Error in download_orders: [WinError 183] Cannot create a file when that file already exists: 'C:\\Users\\Will\\Desktop\\Andrew\\Projects\\RandomStuff\\WorkBot\\main\\backend\\downloads\\Order.pdf' -> 'C:\\Users\\Will\\Desktop\\Andrew\\Projects\\RandomStuff\\WorkBot\\main\\backend\\orders\\OrderFiles\\UNFI _ BAKERY 20250215.pdf'
Traceback (most recent call last):
  File "C:\Users\Will\Desktop\Andrew\Projects\RandomStuff\WorkBot\main\backend\logger\Logger.py", line 83, in wrapper
    return func(*args, **kwargs)
  File "C:\Users\Will\Desktop\Andrew\Projects\RandomStuff\WorkBot\main\backend\craftable_bot\CraftableBot.py", line 202, in download_orders
    if self._process_order_row(store, stale_reference_table_rows[index], vendors, download_pdf, update):
       ~~~~~~~~~~~~~~~~~~~~~~~^^^^^^^^^^^^^^^^^^^^^^^^^^^^^^^^^^^^^^^^^^^^^^^^^^^^^^^^^^^^^^^^^^^^^^^^^
  File "C:\Users\Will\Desktop\Andrew\Projects\RandomStuff\WorkBot\main\backend\craftable_bot\CraftableBot.py", line 257, in _process_order_row
    self._rename_new_order_file(store=store, vendor=row_vendor_name, date=row_date_formatted)
    ~~~~~~~~~~~~~~~~~~~~~~~~~~~^^^^^^^^^^^^^^^^^^^^^^^^^^^^^^^^^^^^^^^^^^^^^^^^^^^^^^^^^^^^^^
  File "C:\Users\Will\Desktop\Andrew\Projects\RandomStuff\WorkBot\main\backend\craftable_bot\CraftableBot.py", line 549, in _rename_new_order_file
    original_file.rename(new_filepath)
    ~~~~~~~~~~~~~~~~~~~~^^^^^^^^^^^^^^
  File "C:\Users\Will\AppData\Local\Programs\Python\Python313\Lib\pathlib\_local.py", line 767, in rename
    os.rename(self, target)
    ~~~~~~~~~^^^^^^^^^^^^^^
FileExistsError: [WinError 183] Cannot create a file when that file already exists: 'C:\\Users\\Will\\Desktop\\Andrew\\Projects\\RandomStuff\\WorkBot\\main\\backend\\downloads\\Order.pdf' -> 'C:\\Users\\Will\\Desktop\\Andrew\\Projects\\RandomStuff\\WorkBot\\main\\backend\\orders\\OrderFiles\\UNFI _ BAKERY 20250215.pdf'
2025-02-15 14:21:58,088 - ERROR - backend.craftable_bot.CraftableBot - Error in download_orders: [WinError 183] Cannot create a file when that file already exists: 'C:\\Users\\Will\\Desktop\\Andrew\\Projects\\RandomStuff\\WorkBot\\main\\backend\\downloads\\Order.pdf' -> 'C:\\Users\\Will\\Desktop\\Andrew\\Projects\\RandomStuff\\WorkBot\\main\\backend\\orders\\OrderFiles\\UNFI _ BAKERY 20250215.pdf'
Traceback (most recent call last):
  File "C:\Users\Will\Desktop\Andrew\Projects\RandomStuff\WorkBot\main\backend\logger\Logger.py", line 83, in wrapper
    return func(*args, **kwargs)
  File "C:\Users\Will\Desktop\Andrew\Projects\RandomStuff\WorkBot\main\backend\craftable_bot\CraftableBot.py", line 202, in download_orders
    if self._process_order_row(store, stale_reference_table_rows[index], vendors, download_pdf, update):
       ~~~~~~~~~~~~~~~~~~~~~~~^^^^^^^^^^^^^^^^^^^^^^^^^^^^^^^^^^^^^^^^^^^^^^^^^^^^^^^^^^^^^^^^^^^^^^^^^
  File "C:\Users\Will\Desktop\Andrew\Projects\RandomStuff\WorkBot\main\backend\craftable_bot\CraftableBot.py", line 257, in _process_order_row
    self._rename_new_order_file(store=store, vendor=row_vendor_name, date=row_date_formatted)
    ~~~~~~~~~~~~~~~~~~~~~~~~~~~^^^^^^^^^^^^^^^^^^^^^^^^^^^^^^^^^^^^^^^^^^^^^^^^^^^^^^^^^^^^^^
  File "C:\Users\Will\Desktop\Andrew\Projects\RandomStuff\WorkBot\main\backend\craftable_bot\CraftableBot.py", line 549, in _rename_new_order_file
    original_file.rename(new_filepath)
    ~~~~~~~~~~~~~~~~~~~~^^^^^^^^^^^^^^
  File "C:\Users\Will\AppData\Local\Programs\Python\Python313\Lib\pathlib\_local.py", line 767, in rename
    os.rename(self, target)
    ~~~~~~~~~^^^^^^^^^^^^^^
FileExistsError: [WinError 183] Cannot create a file when that file already exists: 'C:\\Users\\Will\\Desktop\\Andrew\\Projects\\RandomStuff\\WorkBot\\main\\backend\\downloads\\Order.pdf' -> 'C:\\Users\\Will\\Desktop\\Andrew\\Projects\\RandomStuff\\WorkBot\\main\\backend\\orders\\OrderFiles\\UNFI _ BAKERY 20250215.pdf'
2025-02-15 14:22:59,589 - ERROR - backend.craftable_bot.CraftableBot - Error in download_orders: [WinError 183] Cannot create a file when that file already exists: 'C:\\Users\\Will\\Desktop\\Andrew\\Projects\\RandomStuff\\WorkBot\\main\\backend\\downloads\\Order.pdf' -> 'C:\\Users\\Will\\Desktop\\Andrew\\Projects\\RandomStuff\\WorkBot\\main\\backend\\orders\\OrderFiles\\UNFI _ BAKERY 20250215.pdf'
Traceback (most recent call last):
  File "C:\Users\Will\Desktop\Andrew\Projects\RandomStuff\WorkBot\main\backend\logger\Logger.py", line 83, in wrapper
    return func(*args, **kwargs)
  File "C:\Users\Will\Desktop\Andrew\Projects\RandomStuff\WorkBot\main\backend\craftable_bot\CraftableBot.py", line 202, in download_orders
    if self._process_order_row(store, stale_reference_table_rows[index], vendors, download_pdf, update):
       ~~~~~~~~~~~~~~~~~~~~~~~^^^^^^^^^^^^^^^^^^^^^^^^^^^^^^^^^^^^^^^^^^^^^^^^^^^^^^^^^^^^^^^^^^^^^^^^^
  File "C:\Users\Will\Desktop\Andrew\Projects\RandomStuff\WorkBot\main\backend\craftable_bot\CraftableBot.py", line 256, in _process_order_row
    self._rename_new_order_file(store=store, vendor=row_vendor_name, date=row_date_formatted)
    ~~~~~~~~~~~~~~~~~~~~~~~~~~~^^^^^^^^^^^^^^^^^^^^^^^^^^^^^^^^^^^^^^^^^^^^^^^^^^^^^^^^^^^^^^
  File "C:\Users\Will\Desktop\Andrew\Projects\RandomStuff\WorkBot\main\backend\craftable_bot\CraftableBot.py", line 548, in _rename_new_order_file
    original_file.rename(new_filepath)
    ~~~~~~~~~~~~~~~~~~~~^^^^^^^^^^^^^^
  File "C:\Users\Will\AppData\Local\Programs\Python\Python313\Lib\pathlib\_local.py", line 767, in rename
    os.rename(self, target)
    ~~~~~~~~~^^^^^^^^^^^^^^
FileExistsError: [WinError 183] Cannot create a file when that file already exists: 'C:\\Users\\Will\\Desktop\\Andrew\\Projects\\RandomStuff\\WorkBot\\main\\backend\\downloads\\Order.pdf' -> 'C:\\Users\\Will\\Desktop\\Andrew\\Projects\\RandomStuff\\WorkBot\\main\\backend\\orders\\OrderFiles\\UNFI _ BAKERY 20250215.pdf'
2025-02-15 14:24:34,709 - ERROR - backend.craftable_bot.CraftableBot - Error in download_orders: [WinError 183] Cannot create a file when that file already exists: 'C:\\Users\\Will\\Desktop\\Andrew\\Projects\\RandomStuff\\WorkBot\\main\\backend\\downloads\\Order.pdf' -> 'C:\\Users\\Will\\Desktop\\Andrew\\Projects\\RandomStuff\\WorkBot\\main\\backend\\orders\\OrderFiles\\UNFI _ BAKERY 20250215.pdf'
Traceback (most recent call last):
  File "C:\Users\Will\Desktop\Andrew\Projects\RandomStuff\WorkBot\main\backend\logger\Logger.py", line 83, in wrapper
    return func(*args, **kwargs)
  File "C:\Users\Will\Desktop\Andrew\Projects\RandomStuff\WorkBot\main\backend\craftable_bot\CraftableBot.py", line 202, in download_orders
    if self._process_order_row(store, row, vendors, download_pdf, update):
       ~~~~~~~~~~~~~~~~~~~~~~~^^^^^^^^^^^^^^^^^^^^^^^^^^^^^^^^^^^^^^^^^^^
  File "C:\Users\Will\Desktop\Andrew\Projects\RandomStuff\WorkBot\main\backend\craftable_bot\CraftableBot.py", line 256, in _process_order_row
    self._rename_new_order_file(store=store, vendor=row_vendor_name, date=row_date_formatted)
    ~~~~~~~~~~~~~~~~~~~~~~~~~~~^^^^^^^^^^^^^^^^^^^^^^^^^^^^^^^^^^^^^^^^^^^^^^^^^^^^^^^^^^^^^^
  File "C:\Users\Will\Desktop\Andrew\Projects\RandomStuff\WorkBot\main\backend\craftable_bot\CraftableBot.py", line 548, in _rename_new_order_file
    original_file.rename(new_filepath)
    ~~~~~~~~~~~~~~~~~~~~^^^^^^^^^^^^^^
  File "C:\Users\Will\AppData\Local\Programs\Python\Python313\Lib\pathlib\_local.py", line 767, in rename
    os.rename(self, target)
    ~~~~~~~~~^^^^^^^^^^^^^^
FileExistsError: [WinError 183] Cannot create a file when that file already exists: 'C:\\Users\\Will\\Desktop\\Andrew\\Projects\\RandomStuff\\WorkBot\\main\\backend\\downloads\\Order.pdf' -> 'C:\\Users\\Will\\Desktop\\Andrew\\Projects\\RandomStuff\\WorkBot\\main\\backend\\orders\\OrderFiles\\UNFI _ BAKERY 20250215.pdf'
2025-02-15 14:28:21,930 - ERROR - backend.craftable_bot.CraftableBot - Error in download_orders: [WinError 183] Cannot create a file when that file already exists: 'C:\\Users\\Will\\Desktop\\Andrew\\Projects\\RandomStuff\\WorkBot\\main\\backend\\downloads\\Order.pdf' -> 'C:\\Users\\Will\\Desktop\\Andrew\\Projects\\RandomStuff\\WorkBot\\main\\backend\\orders\\OrderFiles\\UNFI _ BAKERY 20250215.pdf'
Traceback (most recent call last):
  File "C:\Users\Will\Desktop\Andrew\Projects\RandomStuff\WorkBot\main\backend\logger\Logger.py", line 83, in wrapper
    return func(*args, **kwargs)
  File "C:\Users\Will\Desktop\Andrew\Projects\RandomStuff\WorkBot\main\backend\craftable_bot\CraftableBot.py", line 202, in download_orders
    if self._process_order_row(store, row, vendors, download_pdf, update):
       ~~~~~~~~~~~~~~~~~~~~~~~^^^^^^^^^^^^^^^^^^^^^^^^^^^^^^^^^^^^^^^^^^^
  File "C:\Users\Will\Desktop\Andrew\Projects\RandomStuff\WorkBot\main\backend\craftable_bot\CraftableBot.py", line 257, in _process_order_row
    self._rename_new_order_file(store=store, vendor=row_vendor_name, date=row_date_formatted)
    ~~~~~~~~~~~~~~~~~~~~~~~~~~~^^^^^^^^^^^^^^^^^^^^^^^^^^^^^^^^^^^^^^^^^^^^^^^^^^^^^^^^^^^^^^
  File "C:\Users\Will\Desktop\Andrew\Projects\RandomStuff\WorkBot\main\backend\craftable_bot\CraftableBot.py", line 549, in _rename_new_order_file
    original_file.rename(new_filepath)
    ~~~~~~~~~~~~~~~~~~~~^^^^^^^^^^^^^^
  File "C:\Users\Will\AppData\Local\Programs\Python\Python313\Lib\pathlib\_local.py", line 767, in rename
    os.rename(self, target)
    ~~~~~~~~~^^^^^^^^^^^^^^
FileExistsError: [WinError 183] Cannot create a file when that file already exists: 'C:\\Users\\Will\\Desktop\\Andrew\\Projects\\RandomStuff\\WorkBot\\main\\backend\\downloads\\Order.pdf' -> 'C:\\Users\\Will\\Desktop\\Andrew\\Projects\\RandomStuff\\WorkBot\\main\\backend\\orders\\OrderFiles\\UNFI _ BAKERY 20250215.pdf'
2025-02-16 06:45:41,570 - ERROR - backend.craftable_bot.CraftableBot - Error in login: 'NoneType' object has no attribute 'get'
Traceback (most recent call last):
  File "C:\Users\Will\Desktop\Andrew\Projects\RandomStuff\WorkBot\main\backend\logger\Logger.py", line 83, in wrapper
    return func(*args, **kwargs)
  File "C:\Users\Will\Desktop\Andrew\Projects\RandomStuff\WorkBot\main\backend\craftable_bot\CraftableBot.py", line 89, in login
    self.driver.get(self.site_map['login_page'])
    ^^^^^^^^^^^^^^^
AttributeError: 'NoneType' object has no attribute 'get'
2025-02-16 12:15:16,750 - ERROR - backend.craftable_bot.CraftableBot - Error in login: Message: 
Stacktrace:
	GetHandleVerifier [0x003702D3+25139]
	(No symbol) [0x002FB284]
	(No symbol) [0x001D04A3]
	(No symbol) [0x00218338]
	(No symbol) [0x0021868B]
	(No symbol) [0x00260F62]
	(No symbol) [0x0023CF84]
	(No symbol) [0x0025E6E1]
	(No symbol) [0x0023CD36]
	(No symbol) [0x0020BD29]
	(No symbol) [0x0020D064]
	GetHandleVerifier [0x0067B193+3215603]
	GetHandleVerifier [0x0069230A+3310186]
	GetHandleVerifier [0x0068C522+3286146]
	GetHandleVerifier [0x00409CD0+654384]
	(No symbol) [0x0030460D]
	(No symbol) [0x003014F8]
	(No symbol) [0x00301697]
	(No symbol) [0x002F3D70]
	BaseThreadInitThunk [0x7673FCC9+25]
	RtlGetAppContainerNamedObjectPath [0x771682AE+286]
	RtlGetAppContainerNamedObjectPath [0x7716827E+238]
Traceback (most recent call last):
  File "C:\Users\Will\Desktop\Andrew\Projects\RandomStuff\WorkBot\main\backend\logger\Logger.py", line 83, in wrapper
    return func(*args, **kwargs)
  File "C:\Users\Will\Desktop\Andrew\Projects\RandomStuff\WorkBot\main\backend\craftable_bot\CraftableBot.py", line 91, in login
    WebDriverWait(self.driver, 30).until(EC.element_to_be_clickable((By.XPATH, './/form')))
    ~~~~~~~~~~~~~~~~~~~~~~~~~~~~~~~~~~~~^^^^^^^^^^^^^^^^^^^^^^^^^^^^^^^^^^^^^^^^^^^^^^^^^^^
  File "C:\Users\Will\Desktop\Andrew\Projects\RandomStuff\venv\Lib\site-packages\selenium\webdriver\support\wait.py", line 146, in until
    raise TimeoutException(message, screen, stacktrace)
selenium.common.exceptions.TimeoutException: Message: 
Stacktrace:
	GetHandleVerifier [0x003702D3+25139]
	(No symbol) [0x002FB284]
	(No symbol) [0x001D04A3]
	(No symbol) [0x00218338]
	(No symbol) [0x0021868B]
	(No symbol) [0x00260F62]
	(No symbol) [0x0023CF84]
	(No symbol) [0x0025E6E1]
	(No symbol) [0x0023CD36]
	(No symbol) [0x0020BD29]
	(No symbol) [0x0020D064]
	GetHandleVerifier [0x0067B193+3215603]
	GetHandleVerifier [0x0069230A+3310186]
	GetHandleVerifier [0x0068C522+3286146]
	GetHandleVerifier [0x00409CD0+654384]
	(No symbol) [0x0030460D]
	(No symbol) [0x003014F8]
	(No symbol) [0x00301697]
	(No symbol) [0x002F3D70]
	BaseThreadInitThunk [0x7673FCC9+25]
	RtlGetAppContainerNamedObjectPath [0x771682AE+286]
	RtlGetAppContainerNamedObjectPath [0x7716827E+238]

2025-02-16 12:16:23,026 - ERROR - backend.craftable_bot.CraftableBot - Error in login: Message: 
Stacktrace:
	GetHandleVerifier [0x00B702D3+25139]
	(No symbol) [0x00AFB284]
	(No symbol) [0x009D04A3]
	(No symbol) [0x00A18338]
	(No symbol) [0x00A1868B]
	(No symbol) [0x00A60F62]
	(No symbol) [0x00A3CF84]
	(No symbol) [0x00A5E6E1]
	(No symbol) [0x00A3CD36]
	(No symbol) [0x00A0BD29]
	(No symbol) [0x00A0D064]
	GetHandleVerifier [0x00E7B193+3215603]
	GetHandleVerifier [0x00E9230A+3310186]
	GetHandleVerifier [0x00E8C522+3286146]
	GetHandleVerifier [0x00C09CD0+654384]
	(No symbol) [0x00B0460D]
	(No symbol) [0x00B014F8]
	(No symbol) [0x00B01697]
	(No symbol) [0x00AF3D70]
	BaseThreadInitThunk [0x7673FCC9+25]
	RtlGetAppContainerNamedObjectPath [0x771682AE+286]
	RtlGetAppContainerNamedObjectPath [0x7716827E+238]
Traceback (most recent call last):
  File "C:\Users\Will\Desktop\Andrew\Projects\RandomStuff\WorkBot\main\backend\logger\Logger.py", line 83, in wrapper
    return func(*args, **kwargs)
  File "C:\Users\Will\Desktop\Andrew\Projects\RandomStuff\WorkBot\main\backend\craftable_bot\CraftableBot.py", line 91, in login
    WebDriverWait(self.driver, 30).until(EC.element_to_be_clickable((By.XPATH, './/form')))
    ~~~~~~~~~~~~~~~~~~~~~~~~~~~~~~~~~~~~^^^^^^^^^^^^^^^^^^^^^^^^^^^^^^^^^^^^^^^^^^^^^^^^^^^
  File "C:\Users\Will\Desktop\Andrew\Projects\RandomStuff\venv\Lib\site-packages\selenium\webdriver\support\wait.py", line 146, in until
    raise TimeoutException(message, screen, stacktrace)
selenium.common.exceptions.TimeoutException: Message: 
Stacktrace:
	GetHandleVerifier [0x00B702D3+25139]
	(No symbol) [0x00AFB284]
	(No symbol) [0x009D04A3]
	(No symbol) [0x00A18338]
	(No symbol) [0x00A1868B]
	(No symbol) [0x00A60F62]
	(No symbol) [0x00A3CF84]
	(No symbol) [0x00A5E6E1]
	(No symbol) [0x00A3CD36]
	(No symbol) [0x00A0BD29]
	(No symbol) [0x00A0D064]
	GetHandleVerifier [0x00E7B193+3215603]
	GetHandleVerifier [0x00E9230A+3310186]
	GetHandleVerifier [0x00E8C522+3286146]
	GetHandleVerifier [0x00C09CD0+654384]
	(No symbol) [0x00B0460D]
	(No symbol) [0x00B014F8]
	(No symbol) [0x00B01697]
	(No symbol) [0x00AF3D70]
	BaseThreadInitThunk [0x7673FCC9+25]
	RtlGetAppContainerNamedObjectPath [0x771682AE+286]
	RtlGetAppContainerNamedObjectPath [0x7716827E+238]

2025-02-16 12:17:43,555 - ERROR - backend.craftable_bot.CraftableBot - Error in login: Message: 
Stacktrace:
	GetHandleVerifier [0x00E702D3+25139]
	(No symbol) [0x00DFB284]
	(No symbol) [0x00CD04A3]
	(No symbol) [0x00D18338]
	(No symbol) [0x00D1868B]
	(No symbol) [0x00D60F62]
	(No symbol) [0x00D3CF84]
	(No symbol) [0x00D5E6E1]
	(No symbol) [0x00D3CD36]
	(No symbol) [0x00D0BD29]
	(No symbol) [0x00D0D064]
	GetHandleVerifier [0x0117B193+3215603]
	GetHandleVerifier [0x0119230A+3310186]
	GetHandleVerifier [0x0118C522+3286146]
	GetHandleVerifier [0x00F09CD0+654384]
	(No symbol) [0x00E0460D]
	(No symbol) [0x00E014F8]
	(No symbol) [0x00E01697]
	(No symbol) [0x00DF3D70]
	BaseThreadInitThunk [0x7673FCC9+25]
	RtlGetAppContainerNamedObjectPath [0x771682AE+286]
	RtlGetAppContainerNamedObjectPath [0x7716827E+238]
Traceback (most recent call last):
  File "C:\Users\Will\Desktop\Andrew\Projects\RandomStuff\WorkBot\main\backend\logger\Logger.py", line 83, in wrapper
    return func(*args, **kwargs)
  File "C:\Users\Will\Desktop\Andrew\Projects\RandomStuff\WorkBot\main\backend\craftable_bot\CraftableBot.py", line 91, in login
    WebDriverWait(self.driver, 30).until(EC.element_to_be_clickable((By.XPATH, './/form')))
    ~~~~~~~~~~~~~~~~~~~~~~~~~~~~~~~~~~~~^^^^^^^^^^^^^^^^^^^^^^^^^^^^^^^^^^^^^^^^^^^^^^^^^^^
  File "C:\Users\Will\Desktop\Andrew\Projects\RandomStuff\venv\Lib\site-packages\selenium\webdriver\support\wait.py", line 146, in until
    raise TimeoutException(message, screen, stacktrace)
selenium.common.exceptions.TimeoutException: Message: 
Stacktrace:
	GetHandleVerifier [0x00E702D3+25139]
	(No symbol) [0x00DFB284]
	(No symbol) [0x00CD04A3]
	(No symbol) [0x00D18338]
	(No symbol) [0x00D1868B]
	(No symbol) [0x00D60F62]
	(No symbol) [0x00D3CF84]
	(No symbol) [0x00D5E6E1]
	(No symbol) [0x00D3CD36]
	(No symbol) [0x00D0BD29]
	(No symbol) [0x00D0D064]
	GetHandleVerifier [0x0117B193+3215603]
	GetHandleVerifier [0x0119230A+3310186]
	GetHandleVerifier [0x0118C522+3286146]
	GetHandleVerifier [0x00F09CD0+654384]
	(No symbol) [0x00E0460D]
	(No symbol) [0x00E014F8]
	(No symbol) [0x00E01697]
	(No symbol) [0x00DF3D70]
	BaseThreadInitThunk [0x7673FCC9+25]
	RtlGetAppContainerNamedObjectPath [0x771682AE+286]
	RtlGetAppContainerNamedObjectPath [0x7716827E+238]

2025-02-16 12:19:31,327 - ERROR - backend.craftable_bot.CraftableBot - Error in login: Message: 
Stacktrace:
	GetHandleVerifier [0x008402D3+25139]
	(No symbol) [0x007CB284]
	(No symbol) [0x006A04A3]
	(No symbol) [0x006E8338]
	(No symbol) [0x006E868B]
	(No symbol) [0x00730F62]
	(No symbol) [0x0070CF84]
	(No symbol) [0x0072E6E1]
	(No symbol) [0x0070CD36]
	(No symbol) [0x006DBD29]
	(No symbol) [0x006DD064]
	GetHandleVerifier [0x00B4B193+3215603]
	GetHandleVerifier [0x00B6230A+3310186]
	GetHandleVerifier [0x00B5C522+3286146]
	GetHandleVerifier [0x008D9CD0+654384]
	(No symbol) [0x007D460D]
	(No symbol) [0x007D14F8]
	(No symbol) [0x007D1697]
	(No symbol) [0x007C3D70]
	BaseThreadInitThunk [0x7673FCC9+25]
	RtlGetAppContainerNamedObjectPath [0x771682AE+286]
	RtlGetAppContainerNamedObjectPath [0x7716827E+238]
Traceback (most recent call last):
  File "C:\Users\Will\Desktop\Andrew\Projects\RandomStuff\WorkBot\main\backend\logger\Logger.py", line 83, in wrapper
    return func(*args, **kwargs)
  File "C:\Users\Will\Desktop\Andrew\Projects\RandomStuff\WorkBot\main\backend\craftable_bot\CraftableBot.py", line 92, in login
    WebDriverWait(self.driver, 30).until(EC.element_to_be_clickable((By.XPATH, './/form')))
    ~~~~~~~~~~~~~~~~~~~~~~~~~~~~~~~~~~~~^^^^^^^^^^^^^^^^^^^^^^^^^^^^^^^^^^^^^^^^^^^^^^^^^^^
  File "C:\Users\Will\Desktop\Andrew\Projects\RandomStuff\venv\Lib\site-packages\selenium\webdriver\support\wait.py", line 146, in until
    raise TimeoutException(message, screen, stacktrace)
selenium.common.exceptions.TimeoutException: Message: 
Stacktrace:
	GetHandleVerifier [0x008402D3+25139]
	(No symbol) [0x007CB284]
	(No symbol) [0x006A04A3]
	(No symbol) [0x006E8338]
	(No symbol) [0x006E868B]
	(No symbol) [0x00730F62]
	(No symbol) [0x0070CF84]
	(No symbol) [0x0072E6E1]
	(No symbol) [0x0070CD36]
	(No symbol) [0x006DBD29]
	(No symbol) [0x006DD064]
	GetHandleVerifier [0x00B4B193+3215603]
	GetHandleVerifier [0x00B6230A+3310186]
	GetHandleVerifier [0x00B5C522+3286146]
	GetHandleVerifier [0x008D9CD0+654384]
	(No symbol) [0x007D460D]
	(No symbol) [0x007D14F8]
	(No symbol) [0x007D1697]
	(No symbol) [0x007C3D70]
	BaseThreadInitThunk [0x7673FCC9+25]
	RtlGetAppContainerNamedObjectPath [0x771682AE+286]
	RtlGetAppContainerNamedObjectPath [0x7716827E+238]

2025-02-16 12:23:16,823 - ERROR - backend.craftable_bot.CraftableBot - Error in download_orders: list index out of range
Traceback (most recent call last):
  File "C:\Users\Will\Desktop\Andrew\Projects\RandomStuff\WorkBot\main\backend\logger\Logger.py", line 83, in wrapper
    return func(*args, **kwargs)
  File "C:\Users\Will\Desktop\Andrew\Projects\RandomStuff\WorkBot\main\backend\craftable_bot\CraftableBot.py", line 197, in download_orders
    self._process_order_row(store, stale_reference_table_rows[pos], vendors, download_pdf, update)
                                   ~~~~~~~~~~~~~~~~~~~~~~~~~~^^^^^
IndexError: list index out of range
2025-02-19 07:53:01,342 - ERROR - backend.craftable_bot.CraftableBot - Error in delete_orders: Message: no such element: Unable to locate element: {"method":"xpath","selector":".//tbody"}
  (Session info: chrome=133.0.6943.100); For documentation on this error, please visit: https://www.selenium.dev/documentation/webdriver/troubleshooting/errors#no-such-element-exception
Stacktrace:
	GetHandleVerifier [0x00310283+25139]
	(No symbol) [0x0029B234]
	(No symbol) [0x001704A3]
	(No symbol) [0x001B8338]
	(No symbol) [0x001B868B]
	(No symbol) [0x00200F62]
	(No symbol) [0x001DCF84]
	(No symbol) [0x001FE6E1]
	(No symbol) [0x001DCD36]
	(No symbol) [0x001ABD29]
	(No symbol) [0x001AD064]
	GetHandleVerifier [0x0061B143+3215603]
	GetHandleVerifier [0x006322BA+3310186]
	GetHandleVerifier [0x0062C4D2+3286146]
	GetHandleVerifier [0x003A9C80+654384]
	(No symbol) [0x002A45BD]
	(No symbol) [0x002A14A8]
	(No symbol) [0x002A1647]
	(No symbol) [0x00293D20]
	BaseThreadInitThunk [0x76F1FCC9+25]
	RtlGetAppContainerNamedObjectPath [0x77A582AE+286]
	RtlGetAppContainerNamedObjectPath [0x77A5827E+238]
	(No symbol) [0x00000000]
Traceback (most recent call last):
  File "C:\Users\Will\Desktop\Andrew\Projects\RandomStuff\WorkBot\main\backend\logger\Logger.py", line 83, in wrapper
    return func(*args, **kwargs)
  File "C:\Users\Will\Desktop\Andrew\Projects\RandomStuff\WorkBot\main\backend\craftable_bot\CraftableBot.py", line 315, in delete_orders
    table_body = self.driver.find_element(By.XPATH, './/tbody')
  File "C:\Users\Will\Desktop\Andrew\Projects\RandomStuff\venv\Lib\site-packages\selenium\webdriver\remote\webdriver.py", line 888, in find_element
    return self.execute(Command.FIND_ELEMENT, {"using": by, "value": value})["value"]
           ~~~~~~~~~~~~^^^^^^^^^^^^^^^^^^^^^^^^^^^^^^^^^^^^^^^^^^^^^^^^^^^^^
  File "C:\Users\Will\Desktop\Andrew\Projects\RandomStuff\venv\Lib\site-packages\selenium\webdriver\remote\webdriver.py", line 429, in execute
    self.error_handler.check_response(response)
    ~~~~~~~~~~~~~~~~~~~~~~~~~~~~~~~~~^^^^^^^^^^
  File "C:\Users\Will\Desktop\Andrew\Projects\RandomStuff\venv\Lib\site-packages\selenium\webdriver\remote\errorhandler.py", line 232, in check_response
    raise exception_class(message, screen, stacktrace)
selenium.common.exceptions.NoSuchElementException: Message: no such element: Unable to locate element: {"method":"xpath","selector":".//tbody"}
  (Session info: chrome=133.0.6943.100); For documentation on this error, please visit: https://www.selenium.dev/documentation/webdriver/troubleshooting/errors#no-such-element-exception
Stacktrace:
	GetHandleVerifier [0x00310283+25139]
	(No symbol) [0x0029B234]
	(No symbol) [0x001704A3]
	(No symbol) [0x001B8338]
	(No symbol) [0x001B868B]
	(No symbol) [0x00200F62]
	(No symbol) [0x001DCF84]
	(No symbol) [0x001FE6E1]
	(No symbol) [0x001DCD36]
	(No symbol) [0x001ABD29]
	(No symbol) [0x001AD064]
	GetHandleVerifier [0x0061B143+3215603]
	GetHandleVerifier [0x006322BA+3310186]
	GetHandleVerifier [0x0062C4D2+3286146]
	GetHandleVerifier [0x003A9C80+654384]
	(No symbol) [0x002A45BD]
	(No symbol) [0x002A14A8]
	(No symbol) [0x002A1647]
	(No symbol) [0x00293D20]
	BaseThreadInitThunk [0x76F1FCC9+25]
	RtlGetAppContainerNamedObjectPath [0x77A582AE+286]
	RtlGetAppContainerNamedObjectPath [0x77A5827E+238]
	(No symbol) [0x00000000]

2025-02-21 14:33:51,696 - ERROR - backend.craftable_bot.CraftableBot - Error in login: Message: invalid session id
Stacktrace:
#0 0x561e78a61bea <unknown>
#1 0x561e784ff623 <unknown>
#2 0x561e78541d7f <unknown>
#3 0x561e78576996 <unknown>
#4 0x561e785711f2 <unknown>
#5 0x561e78570325 <unknown>
#6 0x561e784c8328 <unknown>
#7 0x561e78a2b18b <unknown>
#8 0x561e78a2f112 <unknown>
#9 0x561e78a1804c <unknown>
#10 0x561e78a2fd04 <unknown>
#11 0x561e789fc4bf <unknown>
#12 0x561e784c6d72 <unknown>
#13 0x7f0bf8d41083 __libc_start_main
Traceback (most recent call last):
  File "/home/anigold/projects/IthacaBakery/RandomStuff/WorkBot/main/backend/logger/Logger.py", line 89, in wrapper
    return func(*args, **kwargs)
  File "/home/anigold/projects/IthacaBakery/RandomStuff/WorkBot/main/backend/craftable_bot/CraftableBot.py", line 101, in login
    self.driver.get(self.site_map['login_page'])
    ~~~~~~~~~~~~~~~^^^^^^^^^^^^^^^^^^^^^^^^^^^^^
  File "/home/anigold/projects/IthacaBakery/RandomStuff/venv/lib/python3.13/site-packages/undetected_chromedriver/__init__.py", line 665, in get
    return super().get(url)
           ~~~~~~~~~~~^^^^^
  File "/home/anigold/projects/IthacaBakery/RandomStuff/venv/lib/python3.13/site-packages/selenium/webdriver/remote/webdriver.py", line 454, in get
    self.execute(Command.GET, {"url": url})
    ~~~~~~~~~~~~^^^^^^^^^^^^^^^^^^^^^^^^^^^
  File "/home/anigold/projects/IthacaBakery/RandomStuff/venv/lib/python3.13/site-packages/selenium/webdriver/remote/webdriver.py", line 429, in execute
    self.error_handler.check_response(response)
    ~~~~~~~~~~~~~~~~~~~~~~~~~~~~~~~~~^^^^^^^^^^
  File "/home/anigold/projects/IthacaBakery/RandomStuff/venv/lib/python3.13/site-packages/selenium/webdriver/remote/errorhandler.py", line 232, in check_response
    raise exception_class(message, screen, stacktrace)
selenium.common.exceptions.InvalidSessionIdException: Message: invalid session id
Stacktrace:
#0 0x561e78a61bea <unknown>
#1 0x561e784ff623 <unknown>
#2 0x561e78541d7f <unknown>
#3 0x561e78576996 <unknown>
#4 0x561e785711f2 <unknown>
#5 0x561e78570325 <unknown>
#6 0x561e784c8328 <unknown>
#7 0x561e78a2b18b <unknown>
#8 0x561e78a2f112 <unknown>
#9 0x561e78a1804c <unknown>
#10 0x561e78a2fd04 <unknown>
#11 0x561e789fc4bf <unknown>
#12 0x561e784c6d72 <unknown>
#13 0x7f0bf8d41083 __libc_start_main

2025-02-21 15:50:18,822 - ERROR - backend.craftable_bot.CraftableBot - Error in download_orders: list index out of range
Traceback (most recent call last):
  File "/home/anigold/projects/IthacaBakery/RandomStuff/WorkBot/main/backend/logger/Logger.py", line 89, in wrapper
    return func(*args, **kwargs)
  File "/home/anigold/projects/IthacaBakery/RandomStuff/WorkBot/main/backend/craftable_bot/CraftableBot.py", line 218, in download_orders
    self._process_order_row(store, stale_reference_table_rows[pos], vendors, download_pdf, update)
                                   ~~~~~~~~~~~~~~~~~~~~~~~~~~^^^^^
IndexError: list index out of range
